Requirement already satisfied: pip in /Users/mg20/Library/Application Support/pypoetry/venv/lib/python3.10/site-packages (22.3.1)
WARNING: Retrying (Retry(total=4, connect=None, read=None, redirect=None, status=None)) after connection broken by 'ReadTimeoutError("HTTPSConnectionPool(host='pypi.org', port=443): Read timed out. (read timeout=15)")': /simple/pip/
Collecting pip
  Downloading pip-25.0.1-py3-none-any.whl (1.8 MB)
     ━━━━━━━━━━━╸                             0.5/1.8 MB 6.2 kB/s eta 0:03:31
ERROR: Exception:
Traceback (most recent call last):
  File "/Users/mg20/Library/Application Support/pypoetry/venv/lib/python3.10/site-packages/pip/_vendor/urllib3/response.py", line 437, in _error_catcher
    yield
  File "/Users/mg20/Library/Application Support/pypoetry/venv/lib/python3.10/site-packages/pip/_vendor/urllib3/response.py", line 560, in read
    data = self._fp_read(amt) if not fp_closed else b""
  File "/Users/mg20/Library/Application Support/pypoetry/venv/lib/python3.10/site-packages/pip/_vendor/urllib3/response.py", line 526, in _fp_read
    return self._fp.read(amt) if amt is not None else self._fp.read()
  File "/Users/mg20/Library/Application Support/pypoetry/venv/lib/python3.10/site-packages/pip/_vendor/cachecontrol/filewrapper.py", line 90, in read
    data = self.__fp.read(amt)
  File "/Users/mg20/anaconda3/lib/python3.10/http/client.py", line 465, in read
    s = self.fp.read(amt)
  File "/Users/mg20/anaconda3/lib/python3.10/socket.py", line 705, in readinto
    return self._sock.recv_into(b)
  File "/Users/mg20/anaconda3/lib/python3.10/ssl.py", line 1274, in recv_into
    return self.read(nbytes, buffer)
  File "/Users/mg20/anaconda3/lib/python3.10/ssl.py", line 1130, in read
    return self._sslobj.read(len, buffer)
TimeoutError: The read operation timed out

During handling of the above exception, another exception occurred:

Traceback (most recent call last):
  File "/Users/mg20/Library/Application Support/pypoetry/venv/lib/python3.10/site-packages/pip/_internal/cli/base_command.py", line 160, in exc_logging_wrapper
    status = run_func(*args)
  File "/Users/mg20/Library/Application Support/pypoetry/venv/lib/python3.10/site-packages/pip/_internal/cli/req_command.py", line 247, in wrapper
    return func(self, options, args)
  File "/Users/mg20/Library/Application Support/pypoetry/venv/lib/python3.10/site-packages/pip/_internal/commands/install.py", line 400, in run
    requirement_set = resolver.resolve(
  File "/Users/mg20/Library/Application Support/pypoetry/venv/lib/python3.10/site-packages/pip/_internal/resolution/resolvelib/resolver.py", line 92, in resolve
    result = self._result = resolver.resolve(
  File "/Users/mg20/Library/Application Support/pypoetry/venv/lib/python3.10/site-packages/pip/_vendor/resolvelib/resolvers.py", line 481, in resolve
    state = resolution.resolve(requirements, max_rounds=max_rounds)
  File "/Users/mg20/Library/Application Support/pypoetry/venv/lib/python3.10/site-packages/pip/_vendor/resolvelib/resolvers.py", line 348, in resolve
    self._add_to_criteria(self.state.criteria, r, parent=None)
  File "/Users/mg20/Library/Application Support/pypoetry/venv/lib/python3.10/site-packages/pip/_vendor/resolvelib/resolvers.py", line 172, in _add_to_criteria
    if not criterion.candidates:
  File "/Users/mg20/Library/Application Support/pypoetry/venv/lib/python3.10/site-packages/pip/_vendor/resolvelib/structs.py", line 151, in __bool__
    return bool(self._sequence)
  File "/Users/mg20/Library/Application Support/pypoetry/venv/lib/python3.10/site-packages/pip/_internal/resolution/resolvelib/found_candidates.py", line 155, in __bool__
    return any(self)
  File "/Users/mg20/Library/Application Support/pypoetry/venv/lib/python3.10/site-packages/pip/_internal/resolution/resolvelib/found_candidates.py", line 143, in <genexpr>
    return (c for c in iterator if id(c) not in self._incompatible_ids)
  File "/Users/mg20/Library/Application Support/pypoetry/venv/lib/python3.10/site-packages/pip/_internal/resolution/resolvelib/found_candidates.py", line 97, in _iter_built_with_inserted
    candidate = func()
  File "/Users/mg20/Library/Application Support/pypoetry/venv/lib/python3.10/site-packages/pip/_internal/resolution/resolvelib/factory.py", line 206, in _make_candidate_from_link
    self._link_candidate_cache[link] = LinkCandidate(
  File "/Users/mg20/Library/Application Support/pypoetry/venv/lib/python3.10/site-packages/pip/_internal/resolution/resolvelib/candidates.py", line 297, in __init__
    super().__init__(
  File "/Users/mg20/Library/Application Support/pypoetry/venv/lib/python3.10/site-packages/pip/_internal/resolution/resolvelib/candidates.py", line 162, in __init__
    self.dist = self._prepare()
  File "/Users/mg20/Library/Application Support/pypoetry/venv/lib/python3.10/site-packages/pip/_internal/resolution/resolvelib/candidates.py", line 231, in _prepare
    dist = self._prepare_distribution()
  File "/Users/mg20/Library/Application Support/pypoetry/venv/lib/python3.10/site-packages/pip/_internal/resolution/resolvelib/candidates.py", line 308, in _prepare_distribution
    return preparer.prepare_linked_requirement(self._ireq, parallel_builds=True)
  File "/Users/mg20/Library/Application Support/pypoetry/venv/lib/python3.10/site-packages/pip/_internal/operations/prepare.py", line 491, in prepare_linked_requirement
    return self._prepare_linked_requirement(req, parallel_builds)
  File "/Users/mg20/Library/Application Support/pypoetry/venv/lib/python3.10/site-packages/pip/_internal/operations/prepare.py", line 536, in _prepare_linked_requirement
    local_file = unpack_url(
  File "/Users/mg20/Library/Application Support/pypoetry/venv/lib/python3.10/site-packages/pip/_internal/operations/prepare.py", line 166, in unpack_url
    file = get_http_url(
  File "/Users/mg20/Library/Application Support/pypoetry/venv/lib/python3.10/site-packages/pip/_internal/operations/prepare.py", line 107, in get_http_url
    from_path, content_type = download(link, temp_dir.path)
  File "/Users/mg20/Library/Application Support/pypoetry/venv/lib/python3.10/site-packages/pip/_internal/network/download.py", line 147, in __call__
    for chunk in chunks:
  File "/Users/mg20/Library/Application Support/pypoetry/venv/lib/python3.10/site-packages/pip/_internal/cli/progress_bars.py", line 53, in _rich_progress_bar
    for chunk in iterable:
  File "/Users/mg20/Library/Application Support/pypoetry/venv/lib/python3.10/site-packages/pip/_internal/network/utils.py", line 63, in response_chunks
    for chunk in response.raw.stream(
  File "/Users/mg20/Library/Application Support/pypoetry/venv/lib/python3.10/site-packages/pip/_vendor/urllib3/response.py", line 621, in stream
    data = self.read(amt=amt, decode_content=decode_content)
  File "/Users/mg20/Library/Application Support/pypoetry/venv/lib/python3.10/site-packages/pip/_vendor/urllib3/response.py", line 559, in read
    with self._error_catcher():
  File "/Users/mg20/anaconda3/lib/python3.10/contextlib.py", line 153, in __exit__
    self.gen.throw(typ, value, traceback)
  File "/Users/mg20/Library/Application Support/pypoetry/venv/lib/python3.10/site-packages/pip/_vendor/urllib3/response.py", line 442, in _error_catcher
    raise ReadTimeoutError(self._pool, None, "Read timed out.")
pip._vendor.urllib3.exceptions.ReadTimeoutError: HTTPSConnectionPool(host='files.pythonhosted.org', port=443): Read timed out.

Traceback:

  File "<stdin>", line 937, in main
  File "<stdin>", line 574, in run
  File "<stdin>", line 595, in install
  File "/Users/mg20/anaconda3/lib/python3.10/contextlib.py", line 135, in __enter__
    return next(self.gen)
  File "<stdin>", line 667, in make_env
  File "<stdin>", line 653, in make_env
  File "<stdin>", line 366, in make
  File "<stdin>", line 389, in pip
  File "<stdin>", line 386, in python
  File "<stdin>", line 379, in run
